# CATRED create_traces() Parameter Fix Summary

## Issue Resolved
**Error**: `create_traces() got an unexpected keyword argument 'existing_catred_traces'`

## Root Cause
Parameter naming inconsistencies between callback methods and the TraceCreator's `create_traces()` method:

1. **TraceCreator expected**: `existing_catred_traces` and `manual_catred_data`
2. **Callback methods had**: `existing_mer_traces` and `manual_mer_data` 
3. **Parameter mismatch** when callbacks called the TraceCreator

## Solution Applied

### 1. Fixed MainPlotCallbacks parameter names
**File**: `/cluster_visualization/callbacks/main_plot.py`

**Before**:
```python
def create_traces(self, data, show_polygons, show_mer_tiles, relayout_data, catred_mode, 
                 existing_mer_traces=None, manual_mer_data=None, ...):
    return self.trace_creator.create_traces(
        ..., existing_catred_traces=existing_mer_traces, manual_catred_data=manual_mer_data, ...)
```

**After**:
```python
def create_traces(self, data, show_polygons, show_mer_tiles, relayout_data, catred_mode, 
                 existing_catred_traces=None, manual_catred_data=None, ...):
    return self.trace_creator.create_traces(
        ..., existing_catred_traces=existing_catred_traces, manual_catred_data=manual_catred_data, ...)
```

### 2. Fixed fallback method signature
**Before**:
```python
def _create_traces_fallback(self, data, show_polygons, show_mer_tiles, relayout_data, show_catred_mertile_data, ...):
```

**After**:
```python
def _create_traces_fallback(self, data, show_polygons, show_mer_tiles, relayout_data, catred_mode, ...):
```

### 3. Updated fallback method call
**Before**:
```python
return self._create_traces_fallback(..., existing_mer_traces=existing_mer_traces, manual_mer_data=manual_mer_data, ...)
```

**After**:
```python
return self._create_traces_fallback(..., existing_mer_traces=existing_catred_traces, manual_mer_data=manual_catred_data, ...)
```

## Parameter Consistency Matrix

| Component | Parameter Names | Status |
|-----------|----------------|---------|
| TraceCreator | `existing_catred_traces`, `manual_catred_data` | âœ… Standard |
| CATREDCallbacks | `existing_catred_traces`, `manual_catred_data` | âœ… Fixed |
| MainPlotCallbacks | `existing_catred_traces`, `manual_catred_data` | âœ… Fixed |
| Fallback methods | `existing_mer_traces`, `manual_mer_data` | âœ… Internal consistency |

## Verification
âœ… App starts successfully  
âœ… No "unexpected keyword argument" errors
âœ… CATRED mode switching works (unmasked/masked)
âœ… Debug messages show proper data loading
âœ… All three CATRED modes functional

## Files Modified
- `/cluster_visualization/callbacks/main_plot.py`
  - Fixed `create_traces()` parameter names
  - Fixed `_create_traces_fallback()` signature  
  - Updated fallback method calls

The complete masked CATRED implementation is now fully functional without parameter errors! ðŸš€
